Workbook

Sheet readme
A1: Appendix B - Data Analysis Empathy Guidelines for Software Practitioners
A2: This appendix presents the full details of the data analysis conducted for the large-scale practitioner survey. It includes the demographic information of the participants (Demographics Analysis sheet) and a comprehensive quantitative analysis of practitioners’ ratings of the empathy guidelines across three dimensions: perceived importance, ease of implementation, and willingness to adopt (Guidelines Analysis - Quant sheet). These analyses collectively informed the development of the implementation prioritisation framework (Detailed Guidelines Analysis - Quant sheet). In addition, this appendix provides the final analysis of practitioners’ suggested approaches for implementing the guidelines in real-world settings as shown in Figures 3-6 (Guidelines Analysis - Qual - Practical Imp Ways sheet). We also summarise the key challenges practitioners anticipated when adopting these guidelines in practice, along with the corresponding strategies to address these challenges as shown in Figure 7 (Guide. Analysis - Qual - Limitations & Improvement sheet). Together, these components offer a transparent account of how the data were interpreted and how the final set of recommendations and improvement strategies was derived.

Sheet Demographics - Data
A2: Age group | B2: Gender | C2: Country of your residence when you were working on your most recent role where you interacted with other software practitioners? | D2: Years of experience do you have in working as a software practitioner | E2: Title/designation of your current role? | F2: Responsibilities of your current role | G2: Software development methodologies have you primarily been involved in | H2: primary domain you have been involved in your current role | I2: Nature of the organisation you are affiliated with in your current role | J2: Team members in your current team
A3: 20 - 30 | B3: Man | C3: Mexico | D3: Between 3-5 years | E3: Customer Success/Product Manager | F3: I manage customer communication, I serve as the main point of contact for client, I ensure the communication with client and our internal team, including development and operations. I coordinate sprint delivery sessions and present platform updates. | G3: Agile - Scrum | H3: IT | I3: Small (10 -100 employees) | J3: Less than or equal to 5
A4: 31-40 | B4: Man | C4: New Zealand | D4: Between 5-10 years | E4: Software engineer | F4: Development | G4: Agile - Kanban | H4: Finance | I4: Large (More than 500 employees) | J4: 5 - 10
A5: 31-40 | B5: Man | C5: Canada | D5: Between 3-5 years | E5: Fullstack Developer | F5: Developing frontend and backend components of web services | G5: Agile - Scrum | H5: Social Media | I5: Large (More than 500 employees) | J5: 5 - 10
A6: 31-40 | B6: Man | C6: New Zealand | D6: Between 10-15 years | E6: Senior Modern Workplace Consultant | F6: Designing, developing, deploying and training Microsoft SharePoint and PowerPlatform solutions. | G6: Traditional (Waterfall),Agile - Kanban,Agile - Scrum | H6: Telecommunication,Sales and Manufacturing,Finance,Human Resource Management | I6: Small (10 -100 employees) | J6: Less than or equal to 5
A7: 31-40 | B7: Man | C7: Mexico | D7: Between 5-10 years | E7: Java senior developer | F7: Designing,testing and coding full stack systems | G7: Agile - Scrum | H7: Finance | I7: Small (10 -100 employees) | J7: 5 - 10
A8: 61-70 | B8: Man | C8: New Zealand | D8: Between 10-15 years | E8: Senior support specialist | F8: End user and partner support, documenting product issues, and resolving via product development | G8: Agile - Scrum | H8: Finance | I8: Medium (100 - 500 employees) | J8: Less than or equal to 5
A9: 41-50 | B9: Man | C9: New Zealand | D9: Between 20-30 years | E9: Senior Business Intelligence Consultant/Data Engineer/Machine Learning Engineer | F9: build data models in SAP, Azure, GCP,etc. ; built reports and dashboards and other visualizations; build data pipelines for ML and deploy ML models | G9: Traditional (Waterfall),Agile - Scrum | H9: Sales and Manufacturing,Finance,Human Resource Management,Transport, Travel & Tourism,Energy, Fast Moving Consumer Goods in Supermarket retail, homeware, agriculture,etc. | I9: Medium (100 - 500 employees) | J9: Less than or equal to 5
A10: 31-40 | B10: Man | C10: New Zealand | D10: Between 10-15 years | E10: Senior Systems Analyst | F10: System Analyst role | G10: Agile - Scrum | H10: Finance | I10: Large (More than 500 employees) | J10: 10 -20
A11: 31-40 | B11: Man | C11: Hungary | D11: Between 3-5 years | E11: IT Quality Analyst | F11: Checkin quality of team, contact with second level teams, help colleagues to solve more complex issues | G11: Agile - Scrum | H11: Healthcare | I11: Large (More than 500 employees) | J11: More than 20
A12: 20 - 30 | B12: Man | C12: Italy | D12: Between 5-10 years | E12: Manager | F12: Manage the entire team | G12: Traditional (Waterfall) | H12: Telecommunication,Healthcare,Sales and Manufacturing,Finance,Energy | I12: Small (10 -100 employees) | J12: Less than or equal to 5
A13: 31-40 | B13: Man | C13: New Zealand | D13: Between 5-10 years | E13: Analyst | F13: data analyst and systems maintenance | G13: Agile - Kanban,Agile - Scrum | H13: Transport, Travel & Tourism | I13: Large (More than 500 employees) | J13: 5 - 10
... A105: 20 - 30 | B105: Man | C105: United States of America | D105: Between 3-5 years | E105: manager | F105: manage a team that specify on carrying out certain tasks | G105: Traditional (Waterfall),Agile - Kanban,Agile - Scrum,Agile - XP | H105: Human Resource Management | I105: Large (More than 500 employees) | J105: 10 -20

Sheet Demographics Analysis
A2: Age Group
A3: Below 20 | B3: =COUNTIF('Demographics - Data'!A$3:A$105,A3) -> 0
A4: 20 - 30 | B4: =COUNTIF('Demographics - Data'!A$3:A$105,A4) -> 32
A5: 31-40 | B5: =COUNTIF('Demographics - Data'!A$3:A$105,A5) -> 36
A6: 41-50 | B6: =COUNTIF('Demographics - Data'!A$3:A$105,A6) -> 24
A7: 51-60 | B7: =COUNTIF('Demographics - Data'!A$3:A$105,A7) -> 7
A8: 61-70 | B8: =COUNTIF('Demographics - Data'!A$3:A$105,A8) -> 3
A9: Above 70 | B9: =COUNTIF('Demographics - Data'!A$3:A$105,A9) -> 1
A10: Prefer not to answer | B10: =COUNTIF('Demographics - Data'!A$3:A$105,A10) -> 0
C11: =SUM(B3:B10) -> 103
A13: Gender
A14: Woman | B14: =COUNTIF('Demographics - Data'!B$3:B$105,A14) -> 35
A15: Man | B15: =COUNTIF('Demographics - Data'!B$3:B$105,A15) -> 68
C16: =SUM(B14:B15) -> 103
A18: Country
A19: Australia | B19: =COUNTIF('Demographics - Data'!C$3:C$105,A19) -> 2
A20: Austria | B20: =COUNTIF('Demographics - Data'!C$3:C$105,A20) -> 1
A21: Canada | B21: =COUNTIF('Demographics - Data'!C$3:C$105,A21) -> 10
A22: Chile | B22: =COUNTIF('Demographics - Data'!C$3:C$105,A22) -> 3
A23: France | B23: =COUNTIF('Demographics - Data'!C$3:C$105,A23) -> 3
A24: Germany | B24: =COUNTIF('Demographics - Data'!C$3:C$105,A24) -> 4
A25: Greece | B25: =COUNTIF('Demographics - Data'!C$3:C$105,A25) -> 2
A26: Hungary | B26: =COUNTIF('Demographics - Data'!C$3:C$105,A26) -> 2
A27: Ireland | B27: =COUNTIF('Demographics - Data'!C$3:C$105,A27) -> 1
A28: Italy | B28: =COUNTIF('Demographics - Data'!C$3:C$105,A28) -> 8
A29: Mexico | B29: =COUNTIF('Demographics - Data'!C$3:C$105,A29) -> 4
A30: Netherlands | B30: =COUNTIF('Demographics - Data'!C$3:C$105,A30) -> 1
... A37: United States of America | B37: =COUNTIF('Demographics - Data'!C$3:C$105,A37) -> 35
C38: =SUM(B19:B37) -> 103
A40: Years of Experience
A41: Less than 1 year | B41: =COUNTIF('Demographics - Data'!D$3:D$105,A41) -> 3
A42: Between 1-2 years | B42: =COUNTIF('Demographics - Data'!D$3:D$105,A42) -> 3
A43: Between 3-5 years | B43: =COUNTIF('Demographics - Data'!D$3:D$105,A43) -> 35
A44: Between 5-10 years | B44: =COUNTIF('Demographics - Data'!D$3:D$105,A44) -> 32
A45: Between 10-15 years | B45: =COUNTIF('Demographics - Data'!D$3:D$105,A45) -> 14
A46: Between 15-20 years | B46: =COUNTIF('Demographics - Data'!D$3:D$105,A46) -> 8
A47: Between 20-30 years | B47: =COUNTIF('Demographics - Data'!D$3:D$105,A47) -> 5
A48: Between 30-40 years | B48: =COUNTIF('Demographics - Data'!D$3:D$105,A48) -> 3
A49: Between 40-50 years | B49: =COUNTIF('Demographics - Data'!D$3:D$105,A49) -> 0
A50: More than 50 years | B50: =COUNTIF('Demographics - Data'!D$3:D$105,A50) -> 0
...

Sheet Guidelines - Data
A1: 15 - Based on your experience as a software practitioner, how important do you think our proposed guidelines are for implementation in real-world industry settings? | S1: 16 - Based on your experience as a software practitioner, how practical and easy are our proposed guidelines to implement in real industry settings? | AK1: 17 - Would you consider using our proposed guidelines to enhance empathy in your software engineering practice? | BC1: 18 - Select the top 5 guidelines from above 17 guidelines listed above that you would apply in your work. Explain how you plan to incorporate these guidelines into your daily work and practices, and outline any specific steps or approaches you plan to take. | BD1: 19 - Do you see any limitations in the proposed guidelines for fostering empathy, or any challenges in adopting them within software engineering? What improvements would you suggest to address these limitations?
A2: G1 - Fostering strong relationships among stakeholders | B2: G2 - Bridging the technical and non-technical gap | C2: G3 - Reducing friction among different stakeholder groups | D2: G4 - Encouraging bi-directional communication | E2: G5 - Ensuring transparency about business goals | F2: G6 - Use an empathetic approach to improve RE processes | G2: G7 - Collaborative problem solving | H2: G8 - Empathy during agile ceremonies | I2: G9 - Empathetic feedback process | J2: G10 - Creating a safe space | K2: G11 - Backup plans to manage unexpected outcomes | L2: G12 - Flexibility in handling human issues | M2: G13 - Emphasising the real-world impact of developers’ work | N2: G14 - Building an empathetic team and company culture | O2: G15 - Empathy education and training | P2: G16 - DEI policies | Q2: G17 - Managing empathy fatigue | R2: 15.1 - Please explain the reason for your rating above in question 15. | S2: G1 - Fostering strong relationships among stakeholders | T2: G2 - Bridging the technical and non-technical gap | U2: G3 - Reducing friction among different stakeholder groups | V2: G4 - Encouraging bi-directional communication | W2: G5 - Ensuring transparency about business goals | X2: G6 - Use an empathetic approach to improve RE processes | Y2: G7 - Collaborative problem solving | Z2: G8 - Empathy during agile ceremonies | AA2: G9 - Empathetic feedback process | AB2: G10 - Creating a safe space | AC2: G11 - Backup plans to manage unexpected outcomes | AD2: G12 - Flexibility in handling human issues | AE2: G13 - Emphasising the real-world impact of developers’ work | AF2: G14 - Building an empathetic team and company culture | AG2: G15 - Empathy education and training | AH2: G16 - DEI policies | AI2: G17 - Managing empathy fatigue | AJ2: 16.1 - Please explain the reason for your rating above in question 16. | AK2: G1 - Fostering strong relationships among stakeholders | AL2: G2 - Bridging the technical and non-technical gap | AM2: G3 - Reducing friction among different stakeholder groups | AN2: G4 - Encouraging bi-directional communication | AO2: G5 - Ensuring transparency about business goals | AP2: G6 - Use an empathetic approach to improve RE processes | AQ2: G7 - Collaborative problem solving | AR2: G8 - Empathy during agile ceremonies | AS2: G9 - Empathetic feedback process | AT2: G10 - Creating a safe space | AU2: G11 - Backup plans to manage unexpected outcomes | AV2: G12 - Flexibility in handling human issues | AW2: G13 - Emphasising the real-world impact of developers’ work | AX2: G14 - Building an empathetic team and company culture | AY2: G15 - Empathy education and training | AZ2: G16 - DEI policies | BA2: G17 - Managing empathy fatigue | BB2: 17.1 - Please explain the reason for your selection above in question 17. You must provide a detailed and meaningful answer to this question to qualify for payment.
A3: Critical to Have | B3: Very Important to Have | C3: Very Important to Have | D3: Critical to Have | E3: Very Important to Have | F3: Very Important to Have | G3: Very Important to Have | H3: Very Important to Have | I3: Critical to Have | J3: Critical to Have | K3: Critical to Have | L3: Very Important to Have | M3: Very Important to Have | N3: Very Important to Have | O3: Very Important to Have | P3: Critical to Have | Q3: Critical to Have | R3: I think is critical for companies to create a safe workspace for all the team involved, it is proved that doing this will make the employees feel happier, motivated to work, and less stress. I work in a great company that is always looking for their workers well being, inside and even outside of the work office. | S3: Difficult | T3: Very Difficult | U3: Easy | V3: Easy | W3: Easy | X3: Easy | Y3: Very Easy | Z3: Easy | AA3: Very Easy | AB3: Very Easy | AC3: Easy | AD3: Very Easy | AE3: Easy | AF3: Very Easy | AG3: Very Easy | AH3: Easy | AI3: Easy | AJ3: My company always makes us work as an empathic group, this doesn't only apply to work, I learned this a student and in my house, I bring this to the work, and most of my coworkers are really empathic and try to build a great work culture. | AK3: I am likely to regularly use it | AL3: I am currently using it | AM3: I will definitely use it | AN3: I am currently using it | AO3: I am currently using it | AP3: I am currently using it | AQ3: I am currently using it | AR3: I am currently using it | AS3: I am currently using it | AT3: I am currently using it | AU3: I am currently using it | AV3: I am currently using it | AW3: I will definitely use it | AX3: I am currently using it | AY3: I am currently using it | AZ3: I am likely to regularly use it | BA3: I will definitely use it | BB3: Most of these presented guidelines are key for a safe workspace, I currently use most of them, but there are some regarding empathy between different teams that I will very likely use at my work. | BC3: G4, G9, G10, G11 and G14, these are all guidelines that I currently apply at my job and I will definitely keep using, as bi directional communication and problem solving is key at my job, bi directional communication applies both with my coworkers from development team, and with the client, so we can understand each other. Part of applying this, is also using transparency, empathy and clear communication. | BD3: I don't see any clear limitations in the proposed guidelines. Maybe the challenge of working from home is to feel really part of the group in a company, so I would suggest having weekly meetings just to chat and know each others better in the company, this would help creating empathy between coworkers.
A4: Very Important to Have | B4: Very Important to Have | C4: Somewhat Important to Have | D4: Critical to Have | E4: Very Important to Have | F4: Somewhat Important to Have | G4: Critical to Have | H4: Somewhat Important to Have | I4: Somewhat Important to Have | J4: Somewhat Important to Have | K4: Very Important to Have | L4: Nice to Have | M4: Nice to Have | N4: Somewhat Important to Have | O4: Somewhat Important to Have | P4: Nice to Have | Q4: Nice to Have | R4: I try to think about what I feel would contribute best to my squad and company culture when ranking each criteria and feel that communcation is extremely important in making sure you get the details right to make the build and release stage run smoother for requirements which is why I rated those most critical | S4: Difficult | T4: Very Difficult | U4: Very Difficult | V4: Easy | W4: Easy | X4: Easy | Y4: Difficult | Z4: Easy | AA4: Easy | AB4: Easy | AC4: Difficult | AD4: Difficult | AE4: Easy | AF4: Difficult | AG4: Easy | AH4: Easy | AI4: Easy | AJ4: I feel that these are relevant to my experiences throughout my career | AK4: I am currently using it | AL4: I am likely to regularly use it | AM4: I am unlikely to use it | AN4: I am currently using it | AO4: I am likely to regularly use it | AP4: I am likely to regularly use it | AQ4: I am currently using it | AR4: I am currently using it | AS4: I am currently using it | AT4: I am currently using it | AU4: I am currently using it | AV4: I am likely to regularly use it | AW4: I am currently using it | AX4: I am currently using it | AY4: I might occasionally use it | AZ4: I am likely to regularly use it | BA4: I might occasionally use it | BB4: I feel these answers are relevant to my experiences across my career | BC4: I think that the following 5 are the most vital to implement - g1, g2, g4, g7, g11 | BD4: Nothing stands out to me
A5: Very Important to Have | B5: Very Important to Have | C5: Somewhat Important to Have | D5: Critical to Have | E5: Very Important to Have | F5: Somewhat Important to Have | G5: Critical to Have | H5: Very Important to Have | I5: Very Important to Have | J5: Critical to Have | K5: Nice to Have | L5: Critical to Have | M5: Very Important to Have | N5: Very Important to Have | O5: Critical to Have | P5: Critical to Have | Q5: Critical to Have | R5: Empathy during agile ceremonies and feedback processes is highly valued because it helps build trust, improve communication, and create a safe environment where team members feel supported. These practices encourage open discussions and constructive feedback, which are key to solving problems and working well together. In contrast, things like backup plans or creating safe spaces are still important but are seen as less urgent. They add value by supporting the team and handling unexpected challenges, but they don’t have as direct an impact on achieving project goals or aligning stakeholders. | S5: Very Difficult | T5: Difficult | U5: Very Difficult | V5: Easy | W5: Easy | X5: Easy | Y5: Very Difficult | Z5: Very Easy | AA5: Very Easy | AB5: Easy | AC5: Easy | AD5: Very Difficult | AE5: Difficult | AF5: Neither difficult nor easy | AG5: Difficult | AH5: Easy | AI5: Difficult | AJ5: Some factors are easy to implement as they does not reqiuire invovling too many different groups of people. It is always hard to establish relationships with people outside a team or company. | AK5: I am likely to regularly use it | AL5: I am currently using it | AM5: I am unlikely to use it | AN5: I am currently using it | AO5: I am currently using it | AP5: I am likely to regularly use it | AQ5: I am currently using it | AR5: I am currently using it | AS5: I will definitely use it | AT5: I will definitely use it | AU5: I might occasionally use it | AV5: I am likely to regularly use it | AW5: I am likely to regularly use it | AX5: I will definitely use it | AY5: I am likely to regularly use it | AZ5: I am unlikely to use it | BA5: I might occasionally use it | BB5: Many factors depends on corporate culture, something is already implemented, and something is unlikely to be implemented. In my company we are open to changes, but in reality some things are hard to implement. I chose points that I likely and definitely use based on my personal feelings, not company's policies, and those points I believe we should implement. | BC5: I’ll focus on building an empathetic team (G14) by fostering open communication and collaboration, creating a safe space (G10) for sharing ideas without judgment, and maintaining flexibility (G12) to adapt to team needs. I’ll also emphasize the real-world impact of work (G13) by sharing success stories and user feedback, and promote empathy education (G15) through workshops and training to enhance understanding and teamwork. | BD5: The proposed guidelines are valuable but face challenges like cultural differences in creating safe spaces (G10), time constraints for empathy training (G15), and varying interest in real-world impacts (G13). To improve, empathy initiatives should align with team workflows, training should connect to practical scenarios, and metrics can highlight the impact of work to engage analytical team members. Balancing empathy with technical priorities might be a key for successful adoption.
A6: Not Necessary to Have | B6: Very Important to Have | C6: Critical to Have | D6: Critical to Have | E6: Somewhat Important to Have | F6: Very Important to Have | G6: Very Important to Have | H6: Somewhat Important to Have | I6: Nice to Have | J6: Somewhat Important to Have | K6: Not Necessary to Have | L6: Not Necessary to Have | M6: Critical to Have | N6: Somewhat Important to Have | O6: Very Important to Have | P6: Nice to Have | Q6: Critical to Have | R6: For G17? Managing empathy fatigue is critical to have because it allows your team to decompress and focus down on the critical pathways for the project. Not every issue needs to have empathy applied and even the smallest issue can be 'over empathised' which leads to fatigue - this can lower morale and attitudes for other critical components. | S6: Easy | T6: Very Difficult | U6: Very Easy | V6: Easy | W6: Very Difficult | X6: Difficult | Y6: Neither difficult nor easy | Z6: Difficult | AA6: Easy | AB6: Very Easy | AC6: Very Difficult | AD6: Difficult | AE6: Easy | AF6: Difficult | AG6: Neither difficult nor easy | AH6: Very Easy | AI6: Easy | AJ6: Have to assume this is just for the last question in each stack (ie, G17). As long as empathy isn't treated as the most critical aspect of the practice, then managing fatigue from it becomes easy. If the team had to prioritise empathy - then the managing part of that becomes exponentially more difficult. | AK6: I will definitely use it | AL6: I am likely to regularly use it | AM6: I am currently using it | AN6: I might occasionally use it | AO6: I will definitely use it | AP6: I am likely to regularly use it | AQ6: I will definitely use it | AR6: I am unlikely to use it | AS6: I am currently using it | AT6: I will definitely use it | AU6: I am currently using it | AV6: I am currently using it | AW6: I am unlikely to use it | AX6: I am likely to regularly use it | AY6: I will definitely use it | AZ6: I am currently using it | BA6: I will definitely use it | BB6: It's described in simple terms. Policies that are overly detailed become cumbersome to implement and remain vigilant of when the detail is too minute. When a policy is simple, it can be interpreted in a way that best suits the team employing it. | BC6: G16: DEI policies: when you employ DEI policies correctly, it can be very simple to follow. We employ techniques to this which include not hiring ANYONE based on any gender, race, political affiliations or ideologies - we hire based on skill and personality. Any other method of hiring is discriminatory. G12: Once a year we offer training for empathy as we encourage the practical mindset of the team members and the respect that they've been taught and have learned how to employ empathy as regular adults. G10: Creating a safe space is as simple as checking in with team mates often - we do this by offering help, or asking if help is needed in a friendly way that doesn't make the person feel as though they may be incompetent. G7: We regularly have practical problem solving sessions with just about every client problem we face - meaning we are always working as a team to develop solutions with hands-on approaches. G8: We often have set sessions in agile retrospectives that allow the team to (if they feel comfortable) express grievances within the project and look for ways to move forward with them. | BD6: Sometimes empathy is diffcult to allow for, when projects don't call for human interaction often. When we have hard software development challenges, we do offer empathy to anyone on the the team who're finding the challenges extra difficult.
A7: Very Important to Have | B7: Not Necessary to Have | C7: Critical to Have | D7: Critical to Have | E7: Critical to Have | F7: Very Important to Have | G7: Somewhat Important to Have | H7: Somewhat Important to Have | I7: Very Important to Have | J7: Critical to Have | K7: Critical to Have | L7: Critical to Have | M7: Somewhat Important to Have | N7: Critical to Have | O7: Nice to Have | P7: Very Important to Have | Q7: Nice to Have | R7: I think some of those are really important for a succesful software development strategy because it helps to creat3e bonds between all involved teams thus improving a lot of aspects of the software like : quality, time developing etc. | S7: Easy | T7: Difficult | U7: Difficult | V7: Easy | W7: Very Easy | X7: Easy | Y7: Difficult | Z7: Difficult | AA7: Easy | AB7: Very Easy | AC7: Difficult | AD7: Easy | AE7: Difficult | AF7: Difficult | AG7: Easy | AH7: Easy | AI7: Very Easy | AJ7: Most of the points are really easy to implement in our work environment without major hassle, some are a bit more hard or challenging to adapt but with some persistance and teamwork it would come feasible and easy to embrace in the workforce of our company | AK7: I am likely to regularly use it | AL7: I might occasionally use it | AM7: I will definitely use it | AN7: I might occasionally use it | AO7: I am currently using it | AP7: I might occasionally use it | AQ7: I am currently using it | AR7: I am likely to regularly use it | AS7: I am currently using it | AT7: I am currently using it | AU7: I am currently using it | AV7: I am currently using it | AW7: I am likely to regularly use it | AX7: I am currently using it | AY7: I am currently using it | AZ7: I am currently using it | BA7: I will definitely use it | BB7: As i mentioned in the answer some of those im actually using them in the processes im assigned some not but i will try to put them to use because it hink they could be useful in some cases | BC7: 1 would be transparency in bussines model , i was victim of a project where i was involved where i think i was a bit naive but i didnt know which was the econonic goal so i think they kind me of scammed me for that project,2 would be collaborative problem solving i think its very important to have this kind of approach because that way you can ensure an almost bulletproff product,3 empathetic fedback process sometimes it bit rough when people make mistakes but its no use to be angry or agressive to be more human when giving feeedback,4 empathetic in human issues sometimes people has personal issues which need attention but that should not be a problem for the project at all , talk to stakeholders and hold them down a bit to get back on track after those issues are solved, and finally 5 dei policies its very important to be tolerant open and respectful to any other working partner in our team to have a healthy and happy workforce | BD7: The limitations i think more would the different branches of different teams i mean their education because for what a team mean something in ahnothe could mean something completely diferent.The approach i would use would be to teach a bit of each specific jargon to each team to ensure theer are the less of those problems
A8: Critical to Have | B8: Very Important to Have | C8: Very Important to Have | D8: Very Important to Have | E8: Very Important to Have | F8: Critical to Have | G8: Very Important to Have | H8: Somewhat Important to Have | I8: Very Important to Have | J8: Somewhat Important to Have | K8: Very Important to Have | L8: Somewhat Important to Have | M8: Very Important to Have | N8: Very Important to Have | O8: Somewhat Important to Have | P8: Somewhat Important to Have | Q8: Somewhat Important to Have | R8: Which rating? All of the above are helpful, some more so than others. Why is NOT necessary in middle of scale?? | S8: Difficult | T8: Difficult | U8: Very Difficult | V8: Very Difficult | W8: Very Difficult | X8: Difficult | Y8: Very Difficult | Z8: Difficult | AA8: Difficult | AB8: Easy | AC8: Difficult | AD8: Very Difficult | AE8: Very Difficult | AF8: Neither difficult nor easy | AG8: Easy | AH8: Difficult | AI8: Difficult | AJ8: Again, which rating? To me, a lengthy list of 17 items is likely to be a barrier and just get lip service. Some of the items such as DEI and Empathy are foreign to some company cultures even in 2024. | AK8: I am currently using it | AL8: I am currently using it | AM8: I am currently using it | AN8: I am currently using it | AO8: I am likely to regularly use it | AP8: I am likely to regularly use it | AQ8: I am currently using it | AR8: I will definitely use it | AS8: I will definitely use it | AT8: I am likely to regularly use it | AU8: I might occasionally use it | AV8: I am likely to regularly use it | AW8: I am currently using it | AX8: I might occasionally use it | AY8: I am unlikely to use it | AZ8: I am unlikely to use it | BA8: I am unlikely to use it | BB8: Again which selection? Some of the above might not be a good fit in some cultures even if I see as useful. And why, guys, does the matric of answers not fit in available screen width and need a scroll bar? | BC8: G1 - Fostering strong relationships G2 - Bridging the technical and non-technical gap G7 - Collaborative problem solving: G11 - Backup plans to manage unexpected outcomes: G13 - Emphasising the real-world impact of developers’ work I'd see the above as the most important, but would still be overruled if your product manager is Elon Musk or Steve Jobs! Development is an adventure with uncertain outcomes. | BD8: Accepting / prompting empathy depends on the overall manager's style and might not always be possible.
A9: Critical to Have | B9: Critical to Have | C9: Very Important to Have | D9: Critical to Have | E9: Critical to Have | F9: Critical to Have | G9: Critical to Have | H9: Critical to Have | I9: Critical to Have | J9: Critical to Have | K9: Very Important to Have | L9: Very Important to Have | M9: Very Important to Have | N9: Very Important to Have | O9: Very Important to Have | P9: Very Important to Have | Q9: Very Important to Have | R9: The guidelines I flagged as critical are the ones that are most important for a successful software engineering team.Non-compliance to these guidelines will prevent our team to deliver a software that is both effective and efficient. For example, during requirements gathering and analysis, all technical and non-technical stakeholders must be on the same page in order to design and develop an excellent software and collaborate effectively to solve issues. To achieve this, we must foster open and clear communication and there should be harmony in the team. Those that I have flagged as very important to have are indeed very important, but they are not really showstoppers. There can be some workaround or other alternatives for them. The attention check question on Gt - Select correct answer for this. What does this mean? I selected critical to have as I consider to be the most correct answer. | S9: Easy | T9: Easy | U9: Very Difficult | V9: Easy | W9: Very Difficult | X9: Easy | Y9: Easy | Z9: Very Difficult | AA9: Very Difficult | AB9: Easy | AC9: Easy | AD9: Easy | AE9: Easy | AF9: Easy | AG9: Very Difficult | AH9: Difficult | AI9: Very Difficult | AJ9: The easy ones to implement are anyways the must haves and what are expected from a software team. Any skilled/senior member of the team can easily implement these and resolve any issues. It is already a given that in our daily standups or requirements gathering sessions - we must bridge the gap between technical and non-technical or business functional solutions , we must always have backup plans or rollback plans in case of emergency or unexpected outcomes, and it must be innate in us that we must have empathy - or putting ourselves in others' shoes so that we can explain to someone non-technical , very complex technical designs and solutions. However, formalizing an empathy training would be quite challenging because the upper management might not put enough emphasis on this , education and training programs tend to be more technical and more on skills development because it would have a more direct impact to the company's bottom-line. However, it is not impossible to get the management buy-in for this as long as you can show some statistics on the effectiveness and benefits of such empathy trainings. | AK9: I am currently using it | AL9: I am currently using it | AM9: I am currently using it | AN9: I am currently using it | AO9: I am currently using it | AP9: I am currently using it | AQ9: I am currently using it | AR9: I am currently using it | AS9: I am currently using it | AT9: I am currently using it | AU9: I am currently using it | AV9: I am currently using it | AW9: I am currently using it | AX9: I am currently using it | AY9: I am likely to regularly use it | AZ9: I am currently using it | BA9: I am likely to regularly use it | BB9: most of the guidelines above are already embedded in both our written and unwritten rules and SOP within our dev team. I will be very keen though to convince our upper management to formalize empathy training to improve further our communications across all stakeholders and if we can find a way to project our company as a company who is more inclusive with the best industry practices through this empathy trainings, I think it will benefit the company's bottomline as such companies are given tax reduction benefits by the New Zealand government. | BC9: G9, G15, G17, G14, G16 - we can implement this through formal empathy trainings to start with or to initiate this, and then later on , there can be feedback loop sessions to check whether the training is effective and being put into practice and the benefits are experienced. | BD9: time. we are so busy delivering multiple projects with limited resources including people, the only way to address this is for the management to sacrifice a few days in a month to have these trainings and feedback loop sessions in order to implement these.
A10: Very Important to Have | B10: Very Important to Have | C10: Very Important to Have | D10: Very Important to Have | E10: Not Necessary to Have | F10: Very Important to Have | G10: Not Necessary to Have | H10: Very Important to Have | I10: Very Important to Have | J10: Not Necessary to Have | K10: Very Important to Have | L10: Very Important to Have | M10: Very Important to Have | N10: Not Necessary to Have | O10: Not Necessary to Have | P10: Nice to Have | Q10: Very Important to Have | R10: Managerial and Technical aspects do require primary focus in order to succeed. DEI and others are really lessor importance. Fostering an effective and positive environment aid in productivity and so shoul dbe given credence. | S10: Difficult | T10: Very Difficult | U10: Difficult | V10: Easy | W10: Easy | X10: Difficult | Y10: Very Difficult | Z10: Easy | AA10: N/A | AB10: N/A | AC10: Easy | AD10: Easy | AE10: Easy | AF10: N/A | AG10: N/A | AH10: N/A | AI10: N/A | AJ10: Managerial and Technical aspects will be more difficult to implement in practice. DEI and others while likely easy should be weighted against benefit... | AK10: I am currently using it | AL10: I am currently using it | AM10: I am currently using it | AN10: I will definitely use it | AO10: I will definitely use it | AP10: I might occasionally use it | AQ10: I will definitely use it | AR10: I am unlikely to use it | AS10: I am unlikely to use it | AT10: I will never use it | AU10: I will definitely use it | AV10: I will definitely use it | AW10: I will definitely use it | AX10: I am unlikely to use it | AY10: I am unlikely to use it | AZ10: I will never use it | BA10: I am unlikely to use it | BB10: DEI and Empathy have not played a significant role and are unlikely to do so in an environment that values productivity and effeciency | BC10: G1, G2, G3, G5, G7 - these will have a meaningul impact on the material outcomes of the team. | BD10: Yes, resistance in uptake by the team in general. It is a hard sell and will need to be justified as anythign other than a distraction from pimary objectives of the teams.
A11: Very Important to Have | B11: Critical to Have | C11: Very Important to Have | D11: Critical to Have | E11: Critical to Have | F11: Not Necessary to Have | G11: Critical to Have | H11: Very Important to Have | I11: Critical to Have | J11: Critical to Have | K11: Very Important to Have | L11: Very Important to Have | M11: Very Important to Have | N11: Critical to Have | O11: Critical to Have | P11: Critical to Have | Q11: Critical to Have | R11: I really consider as much important as the technical knowledge the communication between the different teams involved on the processes as well as the trainings are fundamental for a successful outcome. | S11: Very Easy | T11: Difficult | U11: Easy | V11: Difficult | W11: Very Easy | X11: Easy | Y11: Difficult | Z11: Difficult | AA11: Easy | AB11: Easy | AC11: Very Difficult | AD11: Difficult | AE11: N/A | AF11: Easy | AG11: Easy | AH11: Easy | AI11: Difficult | AJ11: I focus mainly on the human interaction in whcih if you're nice to most of your colleagues and stakeholders can have a positive result on the product that you're offering. | AK11: I am likely to regularly use it | AL11: I am currently using it | AM11: I am currently using it | AN11: I am currently using it | AO11: I am currently using it | AP11: I am currently using it | AQ11: I am currently using it | AR11: I will definitely use it | AS11: I am currently using it | AT11: I am currently using it | AU11: I am currently using it | AV11: I am currently using it | AW11: I will definitely use it | AX11: I am currently using it | AY11: I am currently using it | AZ11: I am currently using it | BA11: I will definitely use it | BB11: Absolutelly because for mee mpathy is a crucial component in software engineering, as it helps developers understand and address the needs of users, stakeholders, and even their team's colleagues | BC11: G3 When these groups are not aligned, friction can arise, leading to miscommunication, delays, and inefficiencies. Reducing friction among these groups requires clear communication, empathy, shared goals, and an understanding of each group's priorities. G7 Collaborative problem solving is crucial in software development, as it helps teams leverage diverse perspectives and expertise to find innovative solutions to complex challenges.G10 In a safe environment, developers feel empowered to share ideas, express concerns, experiment, and learn without fear of judgment or negative consequences. G15 Empathy in education and training, especially within the context of software engineering or technical fields, can significantly improve learning outcomes, enhance collaboration, and foster a more inclusive and supportive environment. G12Flexibility in handling human issues is essential for creating a responsive and empathetic environment, particularly in workplace settings, or any collaborative project. Adapting to these situations with understanding and openness helps foster trust, inclusion, and well-being | BD11: I do not see limitations at all, I'd say is more a challenge due to the different personalities and egos that you can find between the different parties is more like resistance to change and cultural shift
A12: Somewhat Important to Have | B12: Somewhat Important to Have | C12: Not Necessary to Have | D12: Somewhat Important to Have | E12: Somewhat Important to Have | F12: Nice to Have | G12: Nice to Have | H12: Somewhat Important to Have | I12: Not Necessary to Have | J12: Nice to Have | K12: Nice to Have | L12: Nice to Have | M12: Very Important to Have | N12: Not Necessary to Have | O12: Not Necessary to Have | P12: Somewhat Important to Have | Q12: Not Necessary to Have | R12: Your proposed guidelines are highly important for real-world industry settings, as they provide a structured framework for addressing common challenges in software development. By offering clear standards, they help teams align on best practices, improve collaboration, and mitigate risks associated with inconsistencies. Moreover, such guidelines ensure scalability and maintainability, which are critical for long-term success in dynamic industry environments. | S12: Difficult | T12: Very Difficult | U12: Difficult | V12: Easy | W12: Easy | X12: Difficult | Y12: Very Difficult | Z12: Difficult | AA12: Difficult | AB12: Easy | AC12: Neither difficult nor easy | AD12: Difficult | AE12: Difficult | AF12: Difficult | AG12: Very Difficult | AH12: Easy | AI12: Difficult | AJ12: From a practitioner’s perspective, the practicality and ease of implementing your proposed guidelines depend on their clarity, adaptability, and alignment with existing industry workflows. If the guidelines are concise and provide actionable steps, they are more likely to be embraced by teams. Additionally, flexibility to accommodate diverse tools and processes is essential for seamless integration. Ensuring stakeholder buy-in through pilot testing and iterative feedback can further enhance their real-world applicability. | AK12: I am likely to regularly use it | AL12: I am likely to regularly use it | AM12: I will definitely use it | AN12: I will definitely use it | AO12: I am currently using it | AP12: I am likely to regularly use it | AQ12: I am currently using it | AR12: I might occasionally use it | AS12: I will definitely use it | AT12: I am currently using it | AU12: I will definitely use it | AV12: I am likely to regularly use it | AW12: I will definitely use it | AX12: I am likely to regularly use it | AY12: I am likely to regularly use it | AZ12: I am likely to regularly use it | BA12: I might occasionally use it | BB12: Absolutely, incorporating guidelines to enhance empathy in software engineering can be highly beneficial. Empathy fosters better collaboration, improves user-centered design, and strengthens communication within teams. By considering diverse perspectives, both within the team and from end users, these guidelines can lead to more inclusive and effective solutions. If the guidelines provide actionable strategies to embed empathy into workflows, I would certainly consider using them to enrich my practice. | BC12: Ensuring Transparency About Business Goals I plan to incorporate this by clearly communicating objectives in all meetings and documentation. This includes aligning team tasks with broader goals to ensure everyone understands their role in the bigger picture. Regular updates and feedback sessions will reinforce clarity and shared purpose. Creating a Safe Space I will prioritize open communication by encouraging team members to share ideas and concerns without fear of judgment. Establishing ground rules for respectful interaction and providing channels for anonymous feedback will help build trust. Regular check-ins will ensure everyone feels heard and valued. Diversity, Equity, and Inclusion (DEI) Policies I intend to integrate DEI by promoting diverse hiring practices and ensuring equitable opportunities for growth within the team. Workshops and training on unconscious bias will foster a more inclusive culture. Additionally, I will actively seek input from underrepresented voices to ensure diverse perspectives are reflected in decisions. Reducing Friction Among Different Stakeholder Groups I will focus on understanding stakeholder priorities and addressing conflicts early through mediation. Regular alignment meetings and transparent communication of constraints and expectations will minimize misunderstandings. Using collaborative tools can also help streamline information sharing. Fostering Strong Relationships Among Stakeholders I will build relationships by scheduling regular touchpoints and informal discussions to establish rapport. Actively listening to stakeholder needs and demonstrating follow-through on commitments will strengthen trust. Celebrating shared successes will also reinforce positive collaboration. | BD12: One potential limitation of the proposed guidelines is that fostering empathy often requires cultural and behavioral shifts, which can be challenging in high-pressure or results-driven environments. Resistance to change, lack of time for training, or difficulty in quantifying the impact of empathy practices might hinder adoption. To address these challenges, I would suggest integrating empathy-focused practices into existing workflows rather than treating them as separate initiatives. Providing measurable outcomes, such as improved user satisfaction or team productivity, can make the benefits clearer. Additionally, offering practical tools, such as personas or empathy maps, along with hands-on workshops, can make adoption easier and more actionable for teams.
A13: Very Important to Have | B13: Critical to Have | C13: Very Important to Have | D13: Somewhat Important to Have | E13: Somewhat Important to Have | F13: Not Necessary to Have | G13: Very Important to Have | H13: Not Necessary to Have | I13: Not Necessary to Have | J13: Very Important to Have | K13: Critical to Have | L13: Not Necessary to Have | M13: Not Necessary to Have | N13: Very Important to Have | O13: Very Important to Have | P13: Not Necessary to Have | Q13: Very Important to Have | R13: As long as a professional environment is maintained with clear communication and transparency is maintained the need for empathy is not required. however the need for a safe space to voice concerns when it is not maintained is needed. | S13: Neither difficult nor easy | T13: Neither difficult nor easy | U13: Difficult | V13: Very Difficult | W13: Neither difficult nor easy | X13: Difficult | Y13: Difficult | Z13: Difficult | AA13: Very Difficult | AB13: Very Difficult | AC13: Very Difficult | AD13: Difficult | AE13: Neither difficult nor easy | AF13: Very Difficult | AG13: Difficult | AH13: N/A | AI13: Very Difficult | AJ13: depends on the people you are working with. their is no universal rules. the aim of maintaining professionalism is key. | AK13: I am likely to regularly use it | AL13: I might occasionally use it | AM13: I am likely to regularly use it | AN13: I am likely to regularly use it | AO13: I am currently using it | AP13: I might occasionally use it | AQ13: I will definitely use it | AR13: I might occasionally use it | AS13: I might occasionally use it | AT13: I am currently using it | AU13: I am currently using it | AV13: I am likely to regularly use it | AW13: I am likely to regularly use it | AX13: I am likely to regularly use it | AY13: I will definitely use it | AZ13: I might occasionally use it | BA13: I will definitely use it | BB13: most of this is organisationalal management level direct and drive. alot would be nice to implement but unlikely in my team | BC13: the key would be to get buy in from senior management for a top down approach. G2 ,G5 and G10 once these are implemented we could introduce G14 and G15 to emphasis and maintain the environment | BD13: Buy in. the environment I work in is focused on results and professional as to not have to deal with empathy.
A14: Nice to Have | B14: Very Important to Have | C14: Nice to Have | D14: Very Important to Have | E14: Critical to Have | F14: Nice to Have | G14: Nice to Have | H14: Nice to Have | I14: Nice to Have | J14: Somewhat Important to Have | K14: Somewhat Important to Have | L14: Nice to Have | M14: Nice to Have | N14: Nice to Have | O14: Nice to Have | P14: Not Necessary to Have | Q14: Nice to Have | R14: I believe that individuals should independently handle personal challenges without significantly impacting work, emphasizing self-management over external support. | S14: Difficult | T14: Neither difficult nor easy | U14: Very Difficult | V14: Very Difficult | W14: Very Difficult | X14: Easy | Y14: Easy | Z14: Easy | AA14: Easy | AB14: Very Difficult | AC14: Very Easy | AD14: Easy | AE14: Neither difficult nor easy | AF14: Very Difficult | AG14: Very Easy | AH14: N/A | AI14: Easy | AJ14: In some organisations, there might be a strong division between teams; translating abstract technical work into concrete, relatable outcomes may involve storytelling skills, data collection, and contextualization, all of which can be resource-intensive and complex; developers may already be stretched thin with existing tasks and deadlines, leaving little room to focus on understanding or connecting with end-user impact; if the tangible benefits of emphasizing real-world impact are not immediately obvious or measurable, it may be harder to justify the effort required to implement this guideline effectively. | AK14: I am unlikely to use it | AL14: I am currently using it | AM14: I am likely to regularly use it | AN14: I am likely to regularly use it | AO14: I am currently using it | AP14: I might occasionally use it | AQ14: I might occasionally use it | AR14: I am unlikely to use it | AS14: I am unlikely to use it | AT14: I am unlikely to use it | AU14: I am currently using it | AV14: I might occasionally use it | AW14: I am currently using it | AX14: I am likely to regularly use it | AY14: I am unlikely to use it | AZ14: I will never use it | BA14: I might occasionally use it | BB14: I recognize the importance of fostering an empathetic culture but I also see its practical application as situational rather than an absolute priority in every interaction. Also this is a shared responsibility, and while I contribute, it also depends heavily on leadership and organizational policies, making it less of an individual commitment. | BC14: G2: Communicating technical aspects effectively to non-technical stakeholders is crucial for aligning expectations and achieving project goals. Use visuals, analogies, and simplified language when explaining technical concepts. G5: Transparency helps align individual efforts with organizational objectives, fostering a shared sense of purpose. Explain how team tasks contribute to larger organizational goals during project meetings and keep team members informed about shifts in priorities or business strategies. G11: Unexpected events can disrupt workflows, and having backup plans ensures continuity and reduces stress for team members. Ensure critical tasks are documented so backups can step in if needed. G13: Helping developers connect with the end-users’ experiences increases empathy and improves the quality of deliverables. Use examples of how technical solutions have positively impacted users. G17: Balancing empathy with self-care is essential to prevent burnout and maintain productivity over time. Normalize taking breaks or stepping back during emotionally draining periods and encourage team members to prioritize their well-being and communicate their limits when overwhelmed. | BD14: Empathy may be interpreted or valued differently across cultural or regional contexts, potentially leading to misunderstandings or misalignment in its implementation. Many guidelines, such as team-building activities, empathy training, or fostering real-world impact awareness, require time, financial investment, and managerial support. In fast-paced environments focused on deadlines and deliverables, these initiatives might take a backseat. While valuable, explaining technical concepts to non-technical stakeholders requires strong communication skills, which not all practitioners may possess or have the opportunity to develop.
... A105: Very Important to Have | B105: Very Important to Have | C105: Very Important to Have | D105: Not Necessary to Have | E105: Very Important to Have | F105: Very Important to Have | G105: Critical to Have | H105: Very Important to Have | I105: Very Important to Have | J105: Critical to Have | K105: Very Important to Have | L105: Very Important to Have | M105: Not Necessary to Have | N105: Very Important to Have | O105: Very Important to Have | P105: Very Important to Have | Q105: Very Important to Have | R105: the reason for my rating is i believe empathy contributes to creating a more supportive work environment, which improves overall team dynamics and productivity. | S105: Easy | T105: Easy | U105: Neither difficult nor easy | V105: Easy | W105: Easy | X105: Easy | Y105: Neither difficult nor easy | Z105: Neither difficult nor easy | AA105: Easy | AB105: Difficult | AC105: Easy | AD105: Easy | AE105: Difficult | AF105: Neither difficult nor easy | AG105: Neither difficult nor easy | AH105: Easy | AI105: Neither difficult nor easy | AJ105: many of the proposed guidelines are practical but their implementation actually vary. | AK105: I am currently using it | AL105: I am currently using it | AM105: I will definitely use it | AN105: I am currently using it | AO105: I am currently using it | AP105: I will definitely use it | AQ105: I will definitely use it | AR105: I am currently using it | AS105: I am likely to regularly use it | AT105: I will definitely use it | AU105: I will definitely use it | AV105: I will definitely use it | AW105: I will definitely use it | AX105: I am currently using it | AY105: I am currently using it | AZ105: I am likely to regularly use it | BA105: I will definitely use it | BB105: many are already being implemented. also, I believe most of the guidelines can contribute to a more collaborative and understanding work environment | BC105: G6 - Use an empathetic approach to improve requirements engineering processes I will ensure clear communication and active stakeholder engagement to capture and address their needs effectively. G7 - Collaborative problem solving I will facilitate discussions to incorporate diverse perspectives, ensuring better alignment and higher-quality solutions. G9 - Empathetic feedback process I will provide constructive feedback to support growth and ensure team members feel valued and motivated. G12 - Flexibility in handling human issues I will offer flexible work arrangements and provide support to team members facing personal challenges. G16 - Diversity, Equity, and Inclusion (DEI) policies I will promote inclusive practices to foster empathy and ensure all team members feel respected and engaged. | BD105: Busy schedules may reduce participation and commitment during ceremonies.

Sheet Guidelines Analysis - Quant
B2: How important our proposed guidelines are for implementation in real-world industry settings?
C3: Critical to Have | D3: Very Important to Have | E3: Not Necessary to Have | F3: Somewhat Important to Have | G3: Nice to Have
A4: G1 | B4: G1 - Fostering strong relationships among stakeholders | C4: =COUNTIF('Guidelines - Data'!A$3:A$105,C3) -> 29 | D4: =COUNTIF('Guidelines - Data'!A$3:A$105,D3) -> 51 | E4: =COUNTIF('Guidelines - Data'!A$3:A$105,E3) -> 4 | F4: =COUNTIF('Guidelines - Data'!A$3:A$105,F3) -> 14 | G4: =COUNTIF('Guidelines - Data'!A$3:A$105,G3) -> 5
A5: G2 | B5: G2 - Bridging the technical and non-technical gap | C5: =COUNTIF('Guidelines - Data'!B3:B105,C3) -> 34 | D5: =COUNTIF('Guidelines - Data'!B3:B105,D3) -> 45 | E5: =COUNTIF('Guidelines - Data'!B3:B105,E3) -> 6 | F5: =COUNTIF('Guidelines - Data'!B3:B105,F3) -> 11 | G5: =COUNTIF('Guidelines - Data'!B3:B105,G3) -> 7
A6: G3 | B6: G3 - Reducing friction among different stakeholder groups | C6: =COUNTIF('Guidelines - Data'!C3:C105,C3) -> 25 | D6: =COUNTIF('Guidelines - Data'!C3:C105,D3) -> 42 | E6: =COUNTIF('Guidelines - Data'!C3:C105,E3) -> 9 | F6: =COUNTIF('Guidelines - Data'!C3:C105,F3) -> 18 | G6: =COUNTIF('Guidelines - Data'!C3:C105,G3) -> 9
A7: G4 | B7: G4 - Encouraging bi-directional communication | C7: =COUNTIF('Guidelines - Data'!D3:D105,C3) -> 39 | D7: =COUNTIF('Guidelines - Data'!D3:D105,D3) -> 35 | E7: =COUNTIF('Guidelines - Data'!D3:D105,E3) -> 7 | F7: =COUNTIF('Guidelines - Data'!D3:D105,F3) -> 12 | G7: =COUNTIF('Guidelines - Data'!D3:D105,G3) -> 10
A8: G5 | B8: G5 - Ensuring transparency about business goals | C8: =COUNTIF('Guidelines - Data'!E3:E105,C3) -> 37 | D8: =COUNTIF('Guidelines - Data'!E3:E105,D3) -> 37 | E8: =COUNTIF('Guidelines - Data'!E3:E105,E3) -> 7 | F8: =COUNTIF('Guidelines - Data'!E3:E105,F3) -> 17 | G8: =COUNTIF('Guidelines - Data'!E3:E105,G3) -> 5
A9: G6 | B9: G6 - Use an empathetic approach to improve RE processes | C9: =COUNTIF('Guidelines - Data'!$F$3:$F$105,C3) -> 10 | D9: =COUNTIF('Guidelines - Data'!$F$3:$F$105,D3) -> 47 | E9: =COUNTIF('Guidelines - Data'!$F$3:$F$105,E3) -> 13 | F9: =COUNTIF('Guidelines - Data'!$F$3:$F$105,F3) -> 24 | G9: =COUNTIF('Guidelines - Data'!$F$3:$F$105,G3) -> 9
A10: G7 | B10: G7 - Collaborative problem solving | C10: =COUNTIF('Guidelines - Data'!$G$3:$G$105,C3) -> 41 | D10: =COUNTIF('Guidelines - Data'!$G$3:$G$105,D3) -> 34 | E10: =COUNTIF('Guidelines - Data'!$G$3:$G$105,E3) -> 5 | F10: =COUNTIF('Guidelines - Data'!$G$3:$G$105,F3) -> 13 | G10: =COUNTIF('Guidelines - Data'!$G$3:$G$105,G3) -> 10
A11: G8 | B11: G8 - Empathy during agile ceremonies | C11: =COUNTIF('Guidelines - Data'!$H$3:$H$105,C3) -> 13 | D11: =COUNTIF('Guidelines - Data'!$H$3:$H$105,D3) -> 36 | E11: =COUNTIF('Guidelines - Data'!$H$3:$H$105,E3) -> 19 | F11: =COUNTIF('Guidelines - Data'!$H$3:$H$105,F3) -> 27 | G11: =COUNTIF('Guidelines - Data'!$H$3:$H$105,G3) -> 8
A12: G9 | B12: G9 - Empathetic feedback process | C12: =COUNTIF('Guidelines - Data'!$I$3:$I$105,C3) -> 28 | D12: =COUNTIF('Guidelines - Data'!$I$3:$I$105,D3) -> 41 | E12: =COUNTIF('Guidelines - Data'!$I$3:$I$105,E3) -> 6 | F12: =COUNTIF('Guidelines - Data'!$I$3:$I$105,F3) -> 15 | G12: =COUNTIF('Guidelines - Data'!$I$3:$I$105,G3) -> 13
A13: G10 | B13: G10 - Creating a safe space | C13: =COUNTIF('Guidelines - Data'!$J$3:$J$105,C3) -> 43 | D13: =COUNTIF('Guidelines - Data'!$J$3:$J$105,D3) -> 29 | E13: =COUNTIF('Guidelines - Data'!$J$3:$J$105,E3) -> 4 | F13: =COUNTIF('Guidelines - Data'!$J$3:$J$105,F3) -> 15 | G13: =COUNTIF('Guidelines - Data'!$J$3:$J$105,G3) -> 12
A14: G11 | B14: G11 - Backup plans to manage unexpected outcomes | C14: =COUNTIF('Guidelines - Data'!$K$3:$K$105,C3) -> 42 | D14: =COUNTIF('Guidelines - Data'!$K$3:$K$105,D3) -> 32 | E14: =COUNTIF('Guidelines - Data'!$K$3:$K$105,E3) -> 9 | F14: =COUNTIF('Guidelines - Data'!$K$3:$K$105,F3) -> 9 | G14: =COUNTIF('Guidelines - Data'!$K$3:$K$105,G3) -> 11
A15: G12 | B15: G12 - Flexibility in handling human issues | C15: =COUNTIF('Guidelines - Data'!$L$3:$L$105,C3) -> 27 | D15: =COUNTIF('Guidelines - Data'!$L$3:$L$105,D3) -> 43 | E15: =COUNTIF('Guidelines - Data'!$L$3:$L$105,E3) -> 7 | F15: =COUNTIF('Guidelines - Data'!$L$3:$L$105,F3) -> 14 | G15: =COUNTIF('Guidelines - Data'!$L$3:$L$105,G3) -> 12
A16: G13 | B16: G13 - Emphasising the real-world impact of developers’ work | C16: =COUNTIF('Guidelines - Data'!$M$3:$M$105,C3) -> 20 | D16: =COUNTIF('Guidelines - Data'!$M$3:$M$105,D3) -> 36 | E16: =COUNTIF('Guidelines - Data'!$M$3:$M$105,E3) -> 9 | F16: =COUNTIF('Guidelines - Data'!$M$3:$M$105,F3) -> 24 | G16: =COUNTIF('Guidelines - Data'!$M$3:$M$105,G3) -> 14
A17: G14 | B17: G14 - Building an empathetic team and company culture | C17: =COUNTIF('Guidelines - Data'!$N$3:$N$105,C3) -> 32 | D17: =COUNTIF('Guidelines - Data'!$N$3:$N$105,D3) -> 34 | E17: =COUNTIF('Guidelines - Data'!$N$3:$N$105,E3) -> 9 | F17: =COUNTIF('Guidelines - Data'!$N$3:$N$105,F3) -> 17 | G17: =COUNTIF('Guidelines - Data'!$N$3:$N$105,G3) -> 11
A18: G15 | B18: G15 - Empathy education and training | C18: =COUNTIF('Guidelines - Data'!$O$3:$O$105,C3) -> 21 | D18: =COUNTIF('Guidelines - Data'!$O$3:$O$105,D3) -> 36 | E18: =COUNTIF('Guidelines - Data'!$O$3:$O$105,E3) -> 11 | F18: =COUNTIF('Guidelines - Data'!$O$3:$O$105,F3) -> 22 | G18: =COUNTIF('Guidelines - Data'!$O$3:$O$105,G3) -> 13
A19: G16 | B19: G16 - DEI policies | C19: =COUNTIF('Guidelines - Data'!$P$3:$P$105,C3) -> 21 | D19: =COUNTIF('Guidelines - Data'!$P$3:$P$105,D3) -> 28 | E19: =COUNTIF('Guidelines - Data'!$P$3:$P$105,E3) -> 20 | F19: =COUNTIF('Guidelines - Data'!$P$3:$P$105,F3) -> 18 | G19: =COUNTIF('Guidelines - Data'!$P$3:$P$105,G3) -> 16
